Workbook

Sheet Summary
B2: Solar Project — Project Finance Model
B5: 50 MW Solar PPA · 15-year operating life · all figures INR crore
B7: EQUITY IRR | E7: EQUITY NPV | H7: GEARING
B8: =Model!B74 -> 0.12008706 | E8: =Model!B75 -> 13.496922 | H8: =Model!B42/Model!C37 -> 0.7
B9: Levered · post-tax | E9: INR cr @ 10% discount | H9: Debt / CapEx
B11: MINIMUM DSCR | E11: AVERAGE DSCR | H11: PAYBACK BASIS
B12: =MIN(Model!C73:R97) -> 1.5303456 | E12: =AVERAGE(Model!C73:R97) -> 1.6472874 | H12: =Model!B43 -> 63.559322
B13: Lowest annual cover | E13: Mean over tenure | H13: Equity at risk (cr)
B15: PROJECT ECONOMICS
B16: Installed capacity | G16: =Model!B6 -> 50
B17: Initial CapEx (incl. IDC) | G17: =Model!C37 -> 211.86441
B18: Debt drawdown | G18: =Model!B42 -> 148.30508
B19: Equity invested | G19: =Model!B43 -> 63.559322
B20: Debt tenure | G20: =Model!B44 -> 12
B21: Year-1 revenue | G21: =Model!D58 -> 30.66
B22: Year-1 EBITDA | G22: =Model!D60 -> 30.1162
B23: Year-1 EBITDA margin | G23: =Model!D60/Model!D58 -> 0.98226354
B24: Discount rate | G24: =Discount_rate -> 0.1
B26: Outputs link live to the Model tab. Edit blue input cells on Assumptions to run scenarios.

Sheet Assumptions
B2: Assumptions & Inputs
B4: Blue = editable input · Yellow = key scenario lever
B6: CAPACITY & REVENUE
B7: Capacity (MW) | C7: 50 | D7: key lever
B8: Specific yield / capacity factor | C8: 0.2 | D8: key lever
B9: Annual degradation | C9: 0.005
B10: Operational life (years) | C10: 15
B11: Construction period (years) | C11: 1
B12: PPA tariff (INR/MWh) | C12: 3500 | D12: key lever
B13: Annual tariff escalator | C13: 0.02
B14: Yearly hours | C14: 8760
B16: OPERATING EXPENSES
B17: Fixed O&M (INR/MW-year) | C17: 100000
B18: Variable O&M (INR/MWh) | C18: 5
B19: Inflation (O&M escalation) | C19: 0.03
B21: CAPEX & DEBT
B22: Initial CapEx (INR crore) | C22: 200 | D22: key lever
B23: Percent debt (% of CapEx) | C23: 0.7 | D23: key lever
B24: Debt tenure (years) | C24: 12
B25: Debt interest rate (p.a.) | C25: 0.08 | D25: key lever
B26: Debt grace period (years) | C26: 1
B27: Corporate tax rate | C27: 0.25
B28: Depreciation life (years) | C28: 15
B29: Salvage value (% of CapEx) | C29: 0.1
B31: WORKING CAPITAL & RETURNS
B32: Working capital (days revenue) | C32: 30
B33: DSRA requirement (months D/S) | C33: 6
B34: Discount rate | C34: 0.1 | D34: key lever

Sheet Model
A1: Model — Calculation Engine
A3: All figures INR crore unless stated · black = formula · green = linked input · Year 0 = construction
A5: ENERGY & REVENUE
A6: Capacity (MW) | B6: =Capacity -> 50
A7: Capacity Factor | B7: =Capacity_factor -> 0.2
A8: Degradation (annual) | B8: =Ann_degradation -> 0.005
A9: PPA tariff (INR/MWh) | B9: =PPA_tariff -> 3500
A10: Tariff escalator | B10: =Annual_tariff -> 0.02
A11: Hours | B11: =Yearly_hours -> 8760
B12: Year 0 | C12: 1 | D12: 2 | E12: 3 | F12: 4 | G12: 5 | H12: 6 | I12: 7 | J12: 8 | K12: 9 | L12: 10 | M12: 11 | N12: 12 | O12: 13 | P12: 14 | Q12: 15 | R12: 16
A13: Operation Flag | C13: 0 | D13: 1 | E13: 1 | F13: 1 | G13: 1 | H13: 1 | I13: 1 | J13: 1 | K13: 1 | L13: 1 | M13: 1 | N13: 1 | O13: 1 | P13: 1 | Q13: 1 | R13: 1
A14: Energy produced (MWh) | C14: =Capacity*Capacity_factor*Yearly_hours*(1-Ann_degradation)^(C12-2)*C13 -> 0 | D14: =Capacity*Capacity_factor*Yearly_hours*(1-Ann_degradation)^(D12-2)*D13 -> 87600 | E14: =Capacity*Capacity_factor*Yearly_hours*(1-Ann_degradation)^(E12-2)*E13 -> 87162 | F14: =Capacity*Capacity_factor*Yearly_hours*(1-Ann_degradation)^(F12-2)*F13 -> 86726.19 | G14: =Capacity*Capacity_factor*Yearly_hours*(1-Ann_degradation)^(G12-2)*G13 -> 86292.559 | H14: =Capacity*Capacity_factor*Yearly_hours*(1-Ann_degradation)^(H12-2)*H13 -> 85861.096 | I14: =Capacity*Capacity_factor*Yearly_hours*(1-Ann_degradation)^(I12-2)*I13 -> 85431.791 | J14: =Capacity*Capacity_factor*Yearly_hours*(1-Ann_degradation)^(J12-2)*J13 -> 85004.632 | ... R14: =Capacity*Capacity_factor*Yearly_hours*(1-Ann_degradation)^(R12-2)*R13 -> 81663.358
A15: Average tariff (INR/MWh) | C15: =PPA_tariff*(1+Annual_tariff)^(C12-2)*C13 -> 0 | D15: =PPA_tariff*(1+Annual_tariff)^(D12-2)*D13 -> 3500 | E15: =PPA_tariff*(1+Annual_tariff)^(E12-2)*E13 -> 3570 | F15: =PPA_tariff*(1+Annual_tariff)^(F12-2)*F13 -> 3641.4 | G15: =PPA_tariff*(1+Annual_tariff)^(G12-2)*G13 -> 3714.228 | H15: =PPA_tariff*(1+Annual_tariff)^(H12-2)*H13 -> 3788.5126 | I15: =PPA_tariff*(1+Annual_tariff)^(I12-2)*I13 -> 3864.2828 | J15: =PPA_tariff*(1+Annual_tariff)^(J12-2)*J13 -> 3941.5685 | ... R15: =PPA_tariff*(1+Annual_tariff)^(R12-2)*R13 -> 4618.1757
A16: Revenue (INR Crs.) | C16: =C14*C15/10^7 -> 0 | D16: =D14*D15/10^7 -> 30.66 | E16: =E14*E15/10^7 -> 31.116834 | F16: =F14*F15/10^7 -> 31.580475 | G16: =G14*G15/10^7 -> 32.051024 | H16: =H14*H15/10^7 -> 32.528584 | I16: =I14*I15/10^7 -> 33.01326 | J16: =J14*J15/10^7 -> 33.505158 | ... R16: =R14*R15/10^7 -> 37.713574
A18: O&M EXPENSES
B19: Year 0 | C19: 1 | D19: 2 | E19: 3 | F19: 4 | G19: 5 | H19: 6 | I19: 7 | J19: 8 | K19: 9 | L19: 10 | M19: 11 | N19: 12 | O19: 13 | P19: 14 | Q19: 15 | R19: 16
A20: Inflation factor | D20: =(1+Inflation_OM)^(C19-1) -> 1 | E20: =(1+Inflation_OM)^(D19-1) -> 1.03 | F20: =(1+Inflation_OM)^(E19-1) -> 1.0609 | G20: =(1+Inflation_OM)^(F19-1) -> 1.092727 | H20: =(1+Inflation_OM)^(G19-1) -> 1.1255088 | I20: =(1+Inflation_OM)^(H19-1) -> 1.1592741 | J20: =(1+Inflation_OM)^(I19-1) -> 1.1940523 | K20: =(1+Inflation_OM)^(J19-1) -> 1.2298739 | ... R20: =(1+Inflation_OM)^(Q19-1) -> 1.5125897
A21: Fixed Expenses | D21: =Capacity*Fixed_OM*D20/10^7 -> 0.5 | E21: =Capacity*Fixed_OM*E20/10^7 -> 0.515 | F21: =Capacity*Fixed_OM*F20/10^7 -> 0.53045 | G21: =Capacity*Fixed_OM*G20/10^7 -> 0.5463635 | H21: =Capacity*Fixed_OM*H20/10^7 -> 0.5627544 | I21: =Capacity*Fixed_OM*I20/10^7 -> 0.57963704 | J21: =Capacity*Fixed_OM*J20/10^7 -> 0.59702615 | K21: =Capacity*Fixed_OM*K20/10^7 -> 0.61493693 | ... R21: =Capacity*Fixed_OM*R20/10^7 -> 0.75629486
A22: Variable Expenses | D22: =Variable_OM*D14*D20/10^7 -> 0.0438 | E22: =Variable_OM*E14*E20/10^7 -> 0.04488843 | F22: =Variable_OM*F14*F20/10^7 -> 0.046003907 | G22: =Variable_OM*G14*G20/10^7 -> 0.047147105 | H22: =Variable_OM*H14*H20/10^7 -> 0.04831871 | I22: =Variable_OM*I14*I20/10^7 -> 0.04951943 | J22: =Variable_OM*J14*J20/10^7 -> 0.050749988 | K22: =Variable_OM*K14*K20/10^7 -> 0.052011125 | ... R22: =Variable_OM*R14*R20/10^7 -> 0.061761578
A23: Total | D23: =SUM(D21,D22) -> 0.5438 | E23: =SUM(E21,E22) -> 0.55988843 | F23: =SUM(F21,F22) -> 0.57645391 | G23: =SUM(G21,G22) -> 0.5935106 | H23: =SUM(H21,H22) -> 0.61107312 | I23: =SUM(I21,I22) -> 0.62915647 | J23: =SUM(J21,J22) -> 0.64777614 | K23: =SUM(K21,K22) -> 0.66694806 | ... R23: =SUM(R21,R22) -> 0.81805644
A25: WORKING CAPITAL
B26: Year 0 | C26: 1 | D26: 2 | E26: 3 | F26: 4 | G26: 5 | H26: 6 | I26: 7 | J26: 8 | K26: 9 | L26: 10 | M26: 11 | N26: 12 | O26: 13 | P26: 14 | Q26: 15 | R26: 16
A27: Revenue | D27: =D16 -> 30.66 | E27: =E16 -> 31.116834 | F27: =F16 -> 31.580475 | G27: =G16 -> 32.051024 | H27: =H16 -> 32.528584 | I27: =I16 -> 33.01326 | J27: =J16 -> 33.505158 | K27: =K16 -> 34.004384 | ... R27: =R16 -> 37.713574
A28: Working Capital Required | D28: =D16*workex/365 -> 2.52 | E28: =E16*workex/365 -> 2.557548 | F28: =F16*workex/365 -> 2.5956555 | G28: =G16*workex/365 -> 2.6343307 | H28: =H16*workex/365 -> 2.6735823 | I28: =I16*workex/365 -> 2.7134186 | J28: =J16*workex/365 -> 2.7538486 | K28: =K16*workex/365 -> 2.7948809 | ... R28: =R16*workex/365 -> 3.0997458
A29: Working Capital Change | D29: =C28-D28 -> -2.52 | E29: =D28-E28 -> -0.037548 | F29: =E28-F28 -> -0.038107465 | G29: =F28-G28 -> -0.038675266 | H29: =G28-H28 -> -0.039251528 | I29: =H28-I28 -> -0.039836376 | J29: =I28-J28 -> -0.040429938 | K29: =J28-K28 -> -0.041032344 | ... R29: =Q28-R28 -> -0.045508141
A31: CAPEX & DEPRECIATION
B32: Year 0 | C32: 1 | D32: 2 | E32: 3 | F32: 4 | G32: 5 | H32: 6 | I32: 7 | J32: 8 | K32: 9 | L32: 10 | M32: 11 | N32: 12 | O32: 13 | P32: 14 | Q32: 15 | R32: 16
A33: Opening Balance | C33: 0 | D33: =C37 -> 211.86441 | E33: =D37 -> 199.07345 | F33: =E37 -> 186.28249 | G33: =F37 -> 173.49153 | H33: =G37 -> 160.70056 | I33: =H37 -> 147.9096 | J33: =I37 -> 135.11864 | K33: =J37 -> 122.32768 | ... R33: =Q37 -> 32.79096
A34: Addition/Sale | C34: =Initial_capex -> 200 | D34: 0 | E34: 0 | F34: 0 | G34: 0 | H34: 0 | I34: 0 | J34: 0 | K34: 0 | L34: 0 | M34: 0 | N34: 0 | O34: 0 | P34: 0 | Q34: 0 | R34: 0
A35: Capitalization of Interest | C35: =IF(C13=0,C48,0) -> 11.864407 | D35: 0 | E35: 0 | F35: 0 | G35: 0 | H35: 0 | I35: 0 | J35: 0 | K35: 0 | L35: 0 | M35: 0 | N35: 0 | O35: 0 | P35: 0 | Q35: 0 | R35: 0
A36: Depriciation | C36: =-IF(C13=0,0,($C$37-Initial_capex*Salvage)/Op_life) -> 0 | D36: =-IF(D13=0,0,($C$37-Initial_capex*Salvage)/Op_life) -> -12.79096 | E36: =-IF(E13=0,0,($C$37-Initial_capex*Salvage)/Op_life) -> -12.79096 | F36: =-IF(F13=0,0,($C$37-Initial_capex*Salvage)/Op_life) -> -12.79096 | G36: =-IF(G13=0,0,($C$37-Initial_capex*Salvage)/Op_life) -> -12.79096 | H36: =-IF(H13=0,0,($C$37-Initial_capex*Salvage)/Op_life) -> -12.79096 | I36: =-IF(I13=0,0,($C$37-Initial_capex*Salvage)/Op_life) -> -12.79096 | J36: =-IF(J13=0,0,($C$37-Initial_capex*Salvage)/Op_life) -> -12.79096 | ... R36: =-IF(R13=0,0,($C$37-Initial_capex*Salvage)/Op_life) -> -12.79096
A37: Closing Balance | C37: =SUM(C33:C36) -> 211.86441 | D37: =SUM(D33:D36) -> 199.07345 | E37: =SUM(E33:E36) -> 186.28249 | F37: =SUM(F33:F36) -> 173.49153 | G37: =SUM(G33:G36) -> 160.70056 | H37: =SUM(H33:H36) -> 147.9096 | I37: =SUM(I33:I36) -> 135.11864 | J37: =SUM(J33:J36) -> 122.32768 | ... R37: =SUM(R33:R36) -> 20
A39: FINANCING & DEBT SCHEDULE
B40: Year 0 | C40: 1 | D40: 2 | E40: 3 | F40: 4 | G40: 5 | H40: 6 | I40: 7 | J40: 8 | K40: 9 | L40: 10 | M40: 11 | N40: 12 | O40: 13 | P40: 14 | Q40: 15 | R40: 16
A41: CapEx (INR) | B41: =C37 -> 211.86441
A42: Debt drawdown (INR) | B42: =B41*0.7 -> 148.30508
A43: Equity invest (INR) | B43: =B41-B42 -> 63.559322
A44: Debt tenure (years) | B44: =tenure -> 12
A45: Debt interest rate (annum) | B45: =Debt_interest -> 0.08
A47: Opening debt balance | C47: =B51 -> 148.30508 | D47: =C51 -> 148.30508 | E47: =D51 -> 140.49014 | F47: =E51 -> 132.05001 | G47: =F51 -> 122.93466 | H47: =G51 -> 113.09009 | I47: =H51 -> 102.45795 | J47: =I51 -> 90.975243 | ... R47: =Q51 -> -4.3177372e-06
...

Sheet Sensitivity
B2: Sensitivity Analysis
B5: Two-variable data tables · base case highlighted · all figures re-run through the full model
B7: 1 · PPA TARIFF × CAPACITY FACTOR → EQUITY IRR
C8: Capacity Factor
B9: Tariff (INR/MWh) ↓ / → | C9: 0.16 | D9: 0.18 | E9: 0.2 | F9: 0.22 | G9: 0.24
B10: 3000 | C10: 0.033175898 | D10: 0.05945962 | E10: 0.083284463 | F10: 0.10561275 | G10: 0.12709609
B11: 3250 | C11: 0.05097556 | D11: 0.077590949 | E11: 0.10198501 | F11: 0.12537056 | G11: 0.14784962
B12: 3500 | C12: 0.0677574 | D12: 0.094619197 | E12: 0.12008706 | F12: 0.14447737 | G12: 0.16790448
B13: 3750 | C13: 0.083365679 | D13: 0.11114636 | E13: 0.13763797 | F13: 0.16298799 | G13: 0.18732238
B14: 4000 | C14: 0.098373374 | D14: 0.12720855 | E14: 0.15468046 | F14: 0.18095122 | G14: 0.20615758
B15: Base case: tariff 3,500 & CF 20% → 12.0% IRR. Higher tariff and yield both lift levered returns roughly linearly.
B17: 2 · DEBT RATIO × INTEREST RATE → EQUITY IRR
C18: Interest Rate
B19: Debt / CapEx ↓ / → | C19: 0.07 | D19: 0.08 | E19: 0.09 | F19: 0.1 | G19: 0.11
B20: 0.5 | C20: 0.11288152 | D20: 0.10806108 | E20: 0.10313585 | F20: 0.09811064 | G20: 0.09299054
B21: 0.6 | C21: 0.11981729 | D21: 0.11315423 | E21: 0.10635968 | F21: 0.099443042 | G21: 0.092414389
B22: 0.7 | C22: 0.1293167 | D22: 0.12008706 | E22: 0.1107184 | F22: 0.10123123 | G22: 0.091647359
B23: 0.75 | C23: 0.13557258 | D23: 0.12461651 | E23: 0.11354137 | F23: 0.10237838 | G23: 0.090830567
B24: 0.8 | C24: 0.14336778 | D24: 0.13021067 | E24: 0.11699431 | F24: 0.10360788 | G24: 0.089387446
B25: More leverage raises equity IRR (positive leverage) but cheaper debt helps too — the classic gearing trade-off lenders scrutinise.
B27: 3 · CAPACITY FACTOR × PPA TARIFF → EQUITY NPV (INR cr)
C28: Tariff (INR/MWh)
B29: Capacity Factor ↓ / → | C29: 3000 | D29: 3250 | E29: 3500 | F29: 3750 | G29: 4000
B30: 0.16 | C30: -42.129295 | D30: -31.167588 | E30: -20.70392 | F30: -10.819642 | G30: -1.0722243
B31: 0.18 | C31: -25.894675 | D31: -14.500914 | E31: -3.5350697 | F31: 7.430775 | G31: 18.39662
B32: 0.2 | C32: -10.871624 | D32: 1.312648 | E32: 13.49692 | F32: 25.681192 | G32: 37.865464
B33: 0.22 | C33: 3.7235113 | D33: 17.12621 | E33: 30.52891 | F33: 43.931609 | G33: 57.334308
B34: 0.24 | C34: 18.318647 | D34: 32.939773 | E34: 47.560899 | F34: 62.182025 | G34: 76.803152
B35: NPV discounted at 10%. Negative cells show combinations where the project destroys equity value.
B37: 4 · INTEREST RATE × DEBT RATIO → MINIMUM DSCR
C38: Debt / CapEx
B39: Interest Rate ↓ / → | C39: 0.5 | D39: 0.6 | E39: 0.7 | F39: 0.75 | G39: 0.8
B40: 0.07 | C40: 2.3083141 | D40: 1.9096415 | E40: 1.6248754 | F40: 1.510969 | G40: 1.4113008
B41: 0.08 | C41: 2.1787971 | D41: 1.8005337 | E41: 1.5303456 | F41: 1.4222703 | G41: 1.3277045
B42: 0.09 | C42: 2.0594941 | D42: 1.7000711 | E42: 1.4433403 | F42: 1.340648 | G42: 1.2507922
B43: 0.1 | C43: 1.9494238 | D43: 1.6074196 | E43: 1.3631309 | F43: 1.2654155 | G43: 1.1799144
B44: 0.11 | C44: 1.8477122 | D44: 1.521837 | E44: 1.289069 | F44: 1.1959618 | G44: 1.114493
B45: Minimum annual DSCR over the debt tenure. Lenders typically require ≥1.20x; cells below that flag a covenant breach.
